Workbook

Sheet EV.RIESGO
A8: ID del proyecto: | B8: ris001-pe26 | F8: Tipo de Cambio: | G8: Normal | I8: Comentarios adicionales.
A9: Nombre del proyecto | B9: Dale Onboarding Innovador | F9: Prioridad: | G9: Media | I9: SE REQUIEREN PRUEBAS DE NO AFECTACION, PARA PF YA QUE LA FUNCIONALIDAD INCLUYE COMPONENTES ACTUALES
A10: Plataformas impactadas: | B10: Plataforma Dale y componentes PF | F10: Riesgo: | G10: Medio
A11: Líder del Cambio: | B11: Arquitecto | C11: N/A | F11: Afecta la operación: | G11: No
B12: Project Manager | C12: N/A
B13: Líder Técnico Dev | C13: GESTION DE AMBIENTES
A14: Ambiente: | B14: QA3
A16: CUESTIONARIO DE EVALUACIÓN RIESGO
A26: Evaluación de Riesgo | F26: Tiempos de despliegue | J26: Delta máxima permitida
A27: ¿Cuándo realizar el cambio? | B27: Cierre de las sucursales | F27: Actividades Previas | G27: =INT(G32/60) & " H, " & (G32 - INT(G32/60) * 60) & " M" -> 0 H, 0 M | J27: Actividades Previas | L27: =INT(M32/60) & " H, " & (M32 - INT(M32/60) * 60) & " M" -> 0 H, 0 M
A28: ¿Qué implica el cambio? | B28: Ambos (desarrollo de software e infraestructura). | F28: Actividades de Liberación | G28: =INT(G33/60) & " H, " & (G33 - INT(G33/60) * 60) & " M" -> 0 H, 0 M | J28: Actividades de Liberación | L28: =INT(M33/60) & " H, " & (M33 - INT(M33/60) * 60) & " M" -> 0 H, 0 M
A29: ¿Requiere Validaciones? | B29: Sí se requiren pruebas | F29: Actividades de Validación | G29: =INT(G34/60) & " H, " & (G34 - INT(G34/60) * 60) & " M" -> 0 H, 0 M | J29: Actividades de Valición | L29: =INT(M34/60) & " H, " & (M34 - INT(M34/60) * 60) & " M" -> 0 H, 0 M
F30: Actividades de Rollback | G30: =INT(G35/60) & " H, " & (G35 - INT(G35/60) * 60) & " M" -> 0 H, 0 M
F32: Actividades Previas | G32: =SUM(RFC!L32:L35) -> 0 | J32: Actividades Previas | L32: 0.25 | M32: =G32*(1+L32) -> 0
F33: Actividades de Liberación | G33: =SUM(RFC!L88:L224) -> 0 | J33: Actividades de Liberación | L33: 0.25 | M33: =G33*(1+L33) -> 0
F34: Actividades de Valición | G34: =SUM(VALIDACIÓN!J17:J42) -> 0 | J34: Actividades de Valición | L34: 0.5 | M34: =G34*(1+L34) -> 0
F35: Actividades de Rollback | G35: =SUM(ROLLBACK!K31:K183) -> 0 | J35: Actividades de Rollback | L35: 0.5 | M35: =G35*(1+L35) -> 0

Sheet RFC
A8: =EV.RIESGO!A8 -> ID del proyecto: | B8: =EV.RIESGO!B8 -> ris001-pe26 | G8: =EV.RIESGO!F8 -> Tipo de Cambio: | H8: =EV.RIESGO!G8 -> Normal | J8: Emergente | K8: =EV.RIESGO!I8 -> Comentarios adicionales. | Q8: Avance de despliegue
A9: =EV.RIESGO!A9 -> Nombre del proyecto | B9: =EV.RIESGO!B9 -> Dale Onboarding Innovador | G9: =EV.RIESGO!F9 -> Prioridad: | H9: =EV.RIESGO!G9 -> Media | K9: Habilitar DALE como una plataforma de Originación adicional, integrada con los sistemas de Macropay, que permita a clientes nuevos y de recompra el inicio de una presolicitud de crédito sin acudir inicialmente a sucursal | Q9: 0.48
A10: =EV.RIESGO!A10 -> Plataformas impactadas: | B10: =EV.RIESGO!B10 -> Plataforma Dale y componentes PF | G10: =EV.RIESGO!F10 -> Riesgo: | H10: =EV.RIESGO!G10 -> Medio
A11: =EV.RIESGO!A11 -> Líder del Cambio: | B11: =EV.RIESGO!B11 -> Arquitecto | D11: =EV.RIESGO!C11 -> N/A | G11: =EV.RIESGO!F11 -> Afecta la operación: | H11: =EV.RIESGO!G11 -> No
B12: =EV.RIESGO!B12 -> Project Manager | D12: =EV.RIESGO!C12 -> N/A
B13: =EV.RIESGO!B13 -> Líder Técnico Dev | D13: =EV.RIESGO!C13 -> GESTION DE AMBIENTES
A14: =EV.RIESGO!A14 -> Ambiente: | B14: =EV.RIESGO!B14 -> QA3
A16: AREAS INVOLUCRADAS
B18: Área | F18: Área Nom | G18: Ejecutor | I18: Back de ejecutor
B19: Selecciona | F19: Selecciona
B20: Administracion de Bases de Datos | F20: DBA
B21: Aplicaciones | F21: APP
B22: Ciberseguridad | F22: Ciber
B23: Desarrollo | F23: DEV
B24: Devops | F24: Devops
B25: Gestor de identidad y accesos | F25: IAM
B26: Infraestructura Cloud | F26: Cloud
B27: Infraestructura SAP | F27: SAP
A29: ACTIVIDADES PREVIAS
A31: No. Tarea | B31: Descripción de la tarea | H31: Servidor | J31: Nubes/Cuenta | K31: Área Nom | L31: Estimación (Minutos) | M31: Hito | N31: Comentarios | Q31: Estado
B32: Crear llave KMS de forma Customer managed keys con el tipo Symmetric y con las funciones de Encrypt and decrypt Usar Este ARN Key para asginarlo al rol solicitado en el paso siguiente. ejemplo: arn:aws:kms:us-east-1:910617026399:key/xxxxxxxx-xxxx-xxxx-xxxx-xxxxxxxx | Q32: En espera
A35: 1 | B35: Ejecutar los scripts contenidos en el siguiente directorio en base al orden de directorio y nombre del script: scripts/ con base al siguiente orden: 01_ALTER_tb_sfc_ventas_softcredito.sql 02_ALTER_tb_PFM_UsuarioJornada.sql 03_ALTER_tb_SM_General.sql 04_ALTER_sp_pfm_ventas_softcredito.sql 05_CREATE_sp_add_mpf_ventas_excepcion.sql 06_CREATE_sp_TiendasCercanasDale.sql 07_ALTER_sp_Credito_Cobranza_SAG_Ordenes_Pendientes_sel_macropay.sql 08_INSERT_pfm_usuarios_sistema.sql 09_INSERT_incode_config_parametros.sql 10_INSERT_pfm_configuracion_generales.sql 11_ALTER_sp_pfm_add_datos_microfronts.sql 12_ALTER_vw_salesforece_productos.sql | H35: core-database-qa3.macropay.mx | K35: DBA | Q35: Espera
A36: 2 | B36: Migrar y Homologar los siguientes objetos de la BD: MacropayPF tomando como referencia el objeto del ambiente de PROD a QA3. 1. DALE_Flujo 2. DALE_DetalleFlujo 3. DALE_Rechazo | H36: core-database-qa3.macropay.mx | J36: 910617026399 | K36: DBA | Q36: Espera
A37: 3 | B37: Crear pipeline del componente midd-originacion-transacciones-proveedor DNS: https://amiddoriginaciondaleqa3.macropay.mx/ Puerto: 8080 | H37: AWS QA3 | J37: 910617026399 | K37: Devops | Q37: Espera
A38: 4 | B38: Crear pipeline del componente midd-originacion-transacciones-proveedor-token DNS: https://amiddoriginaciondaleqa3.macropay.mx/ Puerto: 3000 | H38: AWS QA3 | J38: 910617026399 | K38: Devops | Q38: Espera
A39: 5 | B39: Crear pipeline del componente midd-originacion-transacciones-macropay DNS: https://amiddtransaccionesdaleqa3.macropay.mx/ Puerto: 8080 | H39: AWS QA3 | J39: 910617026399 | K39: Devops | Q39: Espera
A40: 6 | B40: Migrar la estructura y los datos del siguiente catálogo creado en la BD: MacropayPF tomando como referencia el catálogo del ambiente PROD a QA3. 1. DALE_cat_MotivoRechazo | H40: core-database-qa3.macropay.mx | J40: 910617026399 | K40: DBA | Q40: Espera
A41: 7 | B41: Creación del usuario srv-transacciones-dale_qa3 de acuerdo a la carta responsiva: QA3_26-SOL0316999_srv-transacciones-dale_qa3.pdf | H41: core-database-qa3.macropay.mx | J41: 910617026399 | K41: DBA | Q41: Espera
A42: 8 | B42: Resguardo de documentación carta responsiva: QA3_26-SOL0316999_srv-transacciones-dale_qa3.pdf | H42: AWS QA3 | J42: 910617026399 | K42: IAM | Q42: Espera
A43: 9 | B43: Creación del usuario srv-auth-dale_qa3 de acuerdo a la carta responsiva: QA3_26-SOL0317001_srv-auth-dale_qa3.pdf | H43: core-database-qa3.macropay.mx | J43: 910617026399 | K43: DBA | Q43: Espera
A44: 10 | B44: Resguardo de documentación carta responsiva: QA3_26-SOL0317001_srv-auth-dale_qa3.pdf | H44: AWS QA3 | J44: 910617026399 | K44: IAM | Q44: Espera
A45: 11 | B45: Creación del usuario srv-biometrics_creditos_qa3 de acuerdo a la carta responsiva: QA3_26-SOL0317035_srv-biometric_creditos_qa3.pdf | H45: core-database-qa3.macropay.mx | J45: 910617026399 | K45: DBA | Q45: Espera
A46: 12 | B46: Resguardo de documentación carta responsiva: QA3_26-SOL0317035_srv-biometric_creditos_qa3.pdf | H46: AWS QA3 | J46: 910617026399 | K46: IAM | Q46: Espera
A47: 13 | B47: Actualizar y homologar permisos usuario srv-sales_summary_creditos_qa3 de PROD a QA3 de acuerdo a la carta srv-sales_summary_creditos_qa3.pdf | H47: core-database-qa3.macropay.mx | J47: 910617026399 | K47: DBA | Q47: Espera
... A60: 26 | B60: Crear secrets managers del componente midd-pf-terms en QA3 de acuerdo al archivo: midd-pf-terms.json | H60: AWS QA3 | J60: 910617026399 | K60: Devops | Q60: Espera
Q61: Espera
A62: ACTIVIDADES DE LIBERACION
A64: No. Tarea | B64: Descripción de la tarea | H64: Servidor | J64: Nubes/Cuenta | K64: Área Nom | L64: Estimación (Minutos) | M64: Hito | N64: Comentarios | Q64: Estado
A69: 1 | B69: Realizar el redespliegue de https://github.com/MacropayTD/midd-pf-terms Tarea 1 de la pagina INFRA Y DEVOPS | H69: AWS QA3 | J69: 910617026399 | K69: Devops | Q69: Espera
A70: 2 | B70: Realizar el despliegue de https://github.com/MacropayTD/midd-originacion-transacciones-proveedor Tarea 2 de la pagina INFRA Y DEVOPS | H70: AWS QA3 | J70: 910617026399 | K70: Devops | Q70: Espera
...

Sheet HITOS
A8: =EV.RIESGO!A8 -> ID del proyecto: | B8: =EV.RIESGO!B8 -> ris001-pe26 | F8: =EV.RIESGO!F8 -> Tipo de Cambio: | G8: =EV.RIESGO!G8 -> Normal | I8: =EV.RIESGO!I8 -> Comentarios adicionales.
A9: =EV.RIESGO!A9 -> Nombre del proyecto | B9: =EV.RIESGO!B9 -> Dale Onboarding Innovador | F9: =EV.RIESGO!F9 -> Prioridad: | G9: =EV.RIESGO!G9 -> Media
A10: =EV.RIESGO!A10 -> Plataformas impactadas: | B10: =EV.RIESGO!B10 -> Plataforma Dale y componentes PF | F10: =EV.RIESGO!F10 -> Riesgo: | G10: =EV.RIESGO!G10 -> Medio
A11: =EV.RIESGO!A11 -> Líder del Cambio: | B11: =EV.RIESGO!B11 -> Arquitecto | C11: =EV.RIESGO!C11 -> N/A | F11: =EV.RIESGO!F11 -> Afecta la operación: | G11: =EV.RIESGO!G11 -> No
B12: =EV.RIESGO!B12 -> Project Manager | C12: =EV.RIESGO!C12 -> N/A
B13: =EV.RIESGO!B13 -> Líder Técnico Dev | C13: =EV.RIESGO!C13 -> GESTION DE AMBIENTES
A14: =EV.RIESGO!A14 -> Ambiente: | B14: =EV.RIESGO!B14 -> QA3
A16: No. | B16: Descripción de la validación | I16: Área Nom | J16: Identificador | K16: Comentarios
A17: 1 | I17: Selecciona
A18: 2 | I18: Selecciona
A19: 3 | I19: Selecciona
A20: 4 | I20: Selecciona
A21: 5 | I21: Selecciona
A22: 6 | I22: Selecciona
A23: 7 | I23: Selecciona
A24: 8 | I24: Selecciona
A25: 9 | I25: Selecciona
A26: 10 | I26: Selecciona

Sheet INFRA Y DEVOPS
A8: =EV.RIESGO!A8 -> ID del proyecto: | B8: =EV.RIESGO!B8 -> ris001-pe26 | I8: =EV.RIESGO!F8 -> Tipo de Cambio: | J8: =EV.RIESGO!G8 -> Normal | L8: =EV.RIESGO!I8 -> Comentarios adicionales.
A9: =EV.RIESGO!A9 -> Nombre del proyecto | B9: =EV.RIESGO!B9 -> Dale Onboarding Innovador | I9: =EV.RIESGO!F9 -> Prioridad: | J9: =EV.RIESGO!G9 -> Media
A10: =EV.RIESGO!A10 -> Plataformas impactadas: | B10: =EV.RIESGO!B10 -> Plataforma Dale y componentes PF | I10: =EV.RIESGO!F10 -> Riesgo: | J10: =EV.RIESGO!G10 -> Medio
A11: =EV.RIESGO!A11 -> Líder del Cambio: | B11: =EV.RIESGO!B11 -> Arquitecto | C11: =EV.RIESGO!C11 -> N/A | I11: =EV.RIESGO!F11 -> Afecta la operación: | J11: =EV.RIESGO!G11 -> No
B12: =EV.RIESGO!B12 -> Project Manager | C12: =EV.RIESGO!C12 -> N/A
B13: =EV.RIESGO!B13 -> Líder Técnico Dev | C13: =EV.RIESGO!C13 -> GESTION DE AMBIENTES
A14: =EV.RIESGO!A14 -> Ambiente: | B14: =EV.RIESGO!B14 -> QA3
B16: 1 | E16: 2 | H16: 3 | K16: 4 | N16: 5 | Q16: 6 | T16: 7 | W16: 8 | Z16: 9 | AC16: 10 | AF16: 11 | AI16: 12 | AL16: 13 | AO16: 14
A17: Tipo de Servicio | B17: Server AWS(EKS) | E17: Server AWS(EKS) | H17: Server AWS(EKS) | K17: Server AWS(EKS) | N17: Server AWS(EKS) | Q17: Server AWS(EKS) | T17: Lambda (serveless) | W17: Server AWS(EKS) | Z17: Server AWS(EKS) | AC17: Lambda (serveless) | AF17: Server AWS(EKS) | AI17: Server AWS(EKS) | AL17: Server AWS(EKS) | AO17: Server AWS(EKS) | AR17: Server AWS(EKS) | AU17: Server AWS(EKS) | AX17: Server AWS(EKS)
A18: Tipo de publicacion | B18: Interna (No se expone a internet) | E18: Externa (Se expone a internet) | H18: Externa (Se expone a internet) | K18: Interna (No se expone a internet) | N18: Interna (No se expone a internet) | Q18: Interna (No se expone a internet) | T18: Interna (No se expone a internet) | W18: Interna (No se expone a internet) | Z18: Interna (No se expone a internet) | AC18: Interna (No se expone a internet) | AF18: Interna (No se expone a internet) | AI18: Interna (No se expone a internet) | AL18: Interna (No se expone a internet) | AO18: Interna (No se expone a internet)
A19: Repositorio | B19: https://github.com/MacropayTD/midd-pf-terms | E19: https://github.com/MacropayTD/midd-originacion-transacciones-proveedor | H19: https://github.com/MacropayTD/midd-originacion-transacciones-proveedor-token | K19: https://github.com/MacropayTD/midd-pf-biometric | N19: https://github.com/MacropayTD/midd-originacion-transacciones-macropay | Q19: https://github.com/MacropayTD/midd-pf-personal-data | T19: https://github.com/MacropayTD/back-api-belvo-imms | W19: https://github.com/MacropayTD/midd-pf-score-telcel | Z19: https://github.com/MacropayTD/midd-pf-score | AC19: https://github.com/MacropayTD/Midd-camus-biometrics | AF19: https://github.com/MacropayTD/midd-pf-clienteIncode | AI19: https://github.com/MacropayTD/front-finacing-mf-biometrics-incode | AL19: https://github.com/MacropayTD/front-pf-biometrics | AO19: https://github.com/MacropayTD/back-api-sage-maker
A20: Pull Request | B20: #53 | E20: #48 | H20: #15 | K20: #64 | N20: #55 | Q20: #213 | T20: #48 | W20: #31 | Z20: #241 | AC20: #75 | AF20: #83 | AI20: #181 | AL20: #284 | AO20: #123
A21: Ramas de integración | B21: Release | E21: Release | H21: Release | K21: Release | N21: Release | Q21: Release | T21: Release | W21: Release | Z21: Release | AC21: Release | AF21: Release | AI21: Release | AL21: Release | AO21: Release
A22: Commit | B22: 71284a70feb002550b2b5f9ca13a4d1bcea17241 | E22: 839dc9e9f02bd40ee82e3074de02bf7cde088900 | H22: b37d7dcfabb6e51c491708a25f9eb36efe9c0dc8 | K22: ed7407f73835715df9d01494cccd97f6e0d970cf | N22: fa7a3e1cc6fce1fc7fc1df3284a80b5a98689543 | Q22: 910d821805f8f1f4201a09d7822042cb70701d1a | T22: f600b6cbb72cd23a40990031c238005a9d8d94d2 | W22: 9d3a7afa0f21f774401c05a363c914efc972ea49 | Z22: 723d01655ed7a984463c78948f7a163e5c462091 | AC22: 06dc88504a28ad18cda558c655708ac66ce0ad59 | AF22: d4466c1ff9aec54bdb95a4c5fb63a38c236fc86c | AI22: 57df385ef4534357b89e29ed3e00dfb19564cb16 | AL22: e85ed20137aa42f4214839c18f05879d9286f681 | AO22: 2282f4abef211fe0de77e043db883aa063e349e3
A23: Variables de entorno/Web.config /Archivo de despliegue | B23: Las variables de entorno se encuentran en el archivo: /midd-pf-terms.json | E23: Las variables de entorno se encuentran en el archivo: /midd-originacion-transacciones-proveedor.json | H23: Las variables de entorno se encuentran en el archivo: /midd-originacion-transacciones-proveedor-token.json | K23: Se mantienen las variables existentes | N23: Las variables de entorno se encuentran en el archivo: /midd-originacion-transacciones-macropay.json | Q23: Se mantienen las variables existentes | T23: Las variables de entorno se encuentran en el archivo: /back-api-belvo-imms.json | W23: Se mantienen las variables existentes | Z23: Se mantienen las variables existentes | AC23: Se mantienen las variables existentes | AF23: Se mantienen las variables existentes | AI23: Se mantienen las variables existentes | AL23: Se mantienen las variables existentes | AO23: Se mantienen las variables existentes
A24: URL | B24: https://midd-pf-qa3.macropay.mx | E24: https://amiddoriginaciondale-qa3.macropay.mx | H24: https://amiddoriginaciondale-qa3.macropay.mx | K24: https://midd-pf-qa3.macropay.mx | N24: https://amiddtransaccionesdaleqa3.macropay.mx | Q24: https://midd-pf-qa3.macropay.mx | T24: https://lapibelvoimss-qa3.macropay.mx | W24: https://midd-pf-qa3.macropay.mx | Z24: https://midd-pf-qa3.macropay.mx | AC24: https://mm-uniqueappsync-qa-3.macropay.mx | AF24: https://midd-pf-qa3.macropay.mx | AI24: http://qa3-financing2.macropay.mx | AL24: http://qa3-financing2.macropay.mx | AO24: https://midd-pf-qa3.macropay.mx
A25: TAG/CECO

Sheet VALIDACIÓN
A8: =EV.RIESGO!A8 -> ID del proyecto: | B8: =EV.RIESGO!B8 -> ris001-pe26 | F8: =EV.RIESGO!F8 -> Tipo de Cambio: | G8: =EV.RIESGO!G8 -> Normal | I8: =EV.RIESGO!I8 -> Comentarios adicionales. | N8: Avance de despliegue
A9: =EV.RIESGO!A9 -> Nombre del proyecto | B9: =EV.RIESGO!B9 -> Dale Onboarding Innovador | F9: =EV.RIESGO!F9 -> Prioridad: | G9: =EV.RIESGO!G9 -> Media | N9: =COUNTIF(N17:R18,"Completado")/(COUNTA(N17:R18)) -> 0
A10: =EV.RIESGO!A10 -> Plataformas impactadas: | B10: =EV.RIESGO!B10 -> Plataforma Dale y componentes PF | F10: =EV.RIESGO!F10 -> Riesgo: | G10: =EV.RIESGO!G10 -> Medio
A11: =EV.RIESGO!A11 -> Líder del Cambio: | B11: =EV.RIESGO!B11 -> Arquitecto | C11: =EV.RIESGO!C11 -> N/A | F11: =EV.RIESGO!F11 -> Afecta la operación: | G11: =EV.RIESGO!G11 -> No
B12: =EV.RIESGO!B12 -> Project Manager | C12: =EV.RIESGO!C12 -> N/A
B13: =EV.RIESGO!B13 -> Líder Técnico Dev | C13: =EV.RIESGO!C13 -> GESTION DE AMBIENTES
A14: =EV.RIESGO!A14 -> Ambiente: | B14: =EV.RIESGO!B14 -> QA3
A16: No. | B16: ACTIVIDADES DE VALIDACIÓN | I16: Área Nom | J16: Estimación (Minutos) | K16: Comentarios | N16: Estado
A17: 1 | I17: Selecciona | N17: En espera
A18: 2 | I18: Selecciona | N18: En espera

Sheet ROLLBACK
A8: =EV.RIESGO!A8 -> ID del proyecto: | B8: =EV.RIESGO!B8 -> ris001-pe26 | F8: =EV.RIESGO!F8 -> Tipo de Cambio: | G8: =EV.RIESGO!G8 -> Normal | J8: =EV.RIESGO!I8 -> Comentarios adicionales. | O8: Avance de despliegue
A9: =EV.RIESGO!A9 -> Nombre del proyecto | B9: =EV.RIESGO!B9 -> Dale Onboarding Innovador | F9: =EV.RIESGO!F9 -> Prioridad: | G9: =EV.RIESGO!G9 -> Media | O9: =COUNTIF(O31:S37,"Completado")/(COUNTA(O31:S31,O36:S37)) -> 0
A10: =EV.RIESGO!A10 -> Plataformas impactadas: | B10: =EV.RIESGO!B10 -> Plataforma Dale y componentes PF | F10: =EV.RIESGO!F10 -> Riesgo: | G10: =EV.RIESGO!G10 -> Medio
A11: =EV.RIESGO!A11 -> Líder del Cambio: | B11: =EV.RIESGO!B11 -> Arquitecto | C11: =EV.RIESGO!C11 -> N/A | F11: =EV.RIESGO!F11 -> Afecta la operación: | G11: =EV.RIESGO!G11 -> No
B12: =EV.RIESGO!B12 -> Project Manager | C12: =EV.RIESGO!C12 -> N/A
B13: =EV.RIESGO!B13 -> Líder Técnico Dev | C13: =EV.RIESGO!C13 -> GESTION DE AMBIENTES
A14: =EV.RIESGO!A14 -> Ambiente: | B14: =EV.RIESGO!B14 -> QA3
A16: AREAS INVOLUCRADAS
B18: Área | E18: Área Nom | F18: Ejecutor | H18: Back de ejecutor
B19: Administracion de Bases de Datos | E19: DBA | F19: =RFC!G20 -> 0 | H19: =RFC!I20 -> 0
B20: Aplicaciones | E20: APP | F20: =RFC!G21 -> 0 | H20: =RFC!I21 -> 0
B21: Ciberseguridad | E21: Ciber | F21: =RFC!G22 -> 0 | H21: =RFC!I22 -> 0
B22: Desarrollo | E22: DEV | F22: =RFC!G23 -> 0 | H22: =RFC!I23 -> 0
B23: Devops | E23: Devops | F23: =RFC!G24 -> 0 | H23: =RFC!I24 -> 0
B24: Gestor de identidad y accesos | E24: IAM | F24: =RFC!G25 -> 0 | H24: =RFC!I25 -> 0
B25: Infraestructura Cloud | E25: Cloud | F25: =RFC!G26 -> 0 | H25: =RFC!I26 -> 0
B26: Infraestructura SAP | E26: SAP | F26: =RFC!G27 -> 0 | H26: =RFC!I27 -> 0
A28: ACTIVIDADES DE ROLLBACK
A30: No. Tarea | B30: Descripción de la tarea | G30: Servidor | I30: Nubes/Cuenta | J30: Área Nom | K30: Estimación (Minutos) | L30: Comentarios | O30: Estado
J31: Selecciona | O31: En espera
A33: ACTIVIDADES DE VALIDACIÓN
A35: No. | B35: Descripción de la validación | J35: Área Nom | K35: Estimación (Minutos) | L35: Comentarios | O35: Estado
A36: 1 | J36: Selecciona | O36: En espera
A37: 2 | J37: Selecciona | O37: En espera
