Workbook

Sheet EV.RIESGO
A8: ID del proyecto: | B8: com001-pe26 | td029-bf26 | F8: Tipo de Cambio: | G8: Normal | I8: Comentarios adicionales.
A9: Nombre del proyecto | B9: Club Macropay | Compras con Macropesos no descuentan los Macropesos usados a los clientes | F9: Prioridad: | G9: Alta
A10: Plataformas impactadas: | B10: PF, POS, APP, Mulesfort, Salesforce, Infobip | F10: Riesgo: | G10: Medio
A11: Líder del Cambio: | B11: Arquitecto | C11: Henry Suárez Hernández/Jonathan Mauricio López | F11: Afecta la operación: | G11: Si
B12: Project Manager | C12: Maria Alicia Moguel | Ivan Torres
B13: Líder de Célula | C13: Pablo Genaro Sanchez
B14: Líder Técnico | C14: Pablo Genaro Sanchez
A15: Ambiente: | B15: PROD | F15: Componentes a desplegar: | G15: 8
A17: CUESTIONARIO DE EVALUACIÓN RIESGO
A27: Evaluación de Riesgo | F27: Tiempos de despliegue | J27: Delta máxima permitida
A28: ¿Cuándo realizar el cambio? | B28: Durante el día operativo | F28: Actividades Previas | G28: =INT(G33/60) & " H, " & (G33 - INT(G33/60) * 60) & " M" -> 0 H, 0 M | J28: Actividades Previas | L28: =INT(M33/60) & " H, " & (M33 - INT(M33/60) * 60) & " M" -> 0 H, 0 M
A29: ¿Qué implica el cambio? | B29: Ambos (desarrollo de software e infraestructura). | F29: Actividades de Liberación | G29: =INT(G34/60) & " H, " & (G34 - INT(G34/60) * 60) & " M" -> 0 H, 0 M | J29: Actividades de Liberación | L29: =INT(M34/60) & " H, " & (M34 - INT(M34/60) * 60) & " M" -> 0 H, 0 M
A30: ¿Requiere Validaciones? | B30: Sí se requiren pruebas | F30: Actividades de Validación | G30: =INT(G35/60) & " H, " & (G35 - INT(G35/60) * 60) & " M" -> 0 H, 0 M | J30: Actividades de Valición | L30: =INT(M35/60) & " H, " & (M35 - INT(M35/60) * 60) & " M" -> 0 H, 0 M
F31: Actividades de Rollback | G31: =INT(G36/60) & " H, " & (G36 - INT(G36/60) * 60) & " M" -> 0 H, 0 M
F33: Actividades Previas | G33: =SUM(RFC!K36:K43) -> 0 | J33: Actividades Previas | L33: 0.25 | M33: =G33*(1+L33) -> 0
F34: Actividades de Liberación | G34: =SUM(RFC!K57:K203) -> 0 | J34: Actividades de Liberación | L34: 0.25 | M34: =G34*(1+L34) -> 0
F35: Actividades de Valición | G35: =SUM(VALIDACIÓN!J18:J51) -> 0 | J35: Actividades de Valición | L35: 0.5 | M35: =G35*(1+L35) -> 0
F36: Actividades de Rollback | G36: =SUM(ROLLBACK!K35:K205) -> 0 | J36: Actividades de Rollback | L36: 0.5 | M36: =G36*(1+L36) -> 0

Sheet RFC
A8: =EV.RIESGO!A8 -> ID del proyecto: | B8: =EV.RIESGO!B8 -> com001-pe26 | td029-bf26 | F8: =EV.RIESGO!F8 -> Tipo de Cambio: | G8: =EV.RIESGO!G8 -> Normal | J8: =EV.RIESGO!I8 -> Comentarios adicionales. | P8: Avance de despliegue
A9: =EV.RIESGO!A9 -> Nombre del proyecto | B9: =EV.RIESGO!B9 -> Club Macropay | Compras con Macropesos no descuentan los Macropesos usados a los clientes | F9: =EV.RIESGO!F9 -> Prioridad: | G9: =EV.RIESGO!G9 -> Alta | P9: =COUNTIF(P36:T54,"Completado")/(COUNTA(P36:T43,P53:T54)) -> 0
A10: =EV.RIESGO!A10 -> Plataformas impactadas: | B10: =EV.RIESGO!B10 -> PF, POS, APP, Mulesfort, Salesforce, Infobip | F10: =EV.RIESGO!F10 -> Riesgo: | G10: =EV.RIESGO!G10 -> Medio
A11: =EV.RIESGO!A11 -> Líder del Cambio: | B11: =EV.RIESGO!B11 -> Arquitecto | C11: =EV.RIESGO!C11 -> Henry Suárez Hernández/Jonathan Mauricio López | F11: =EV.RIESGO!F11 -> Afecta la operación: | G11: =EV.RIESGO!G11 -> Si
B12: =EV.RIESGO!B12 -> Project Manager | C12: =EV.RIESGO!C12 -> Maria Alicia Moguel | Ivan Torres
B13: =EV.RIESGO!B13 -> Líder de Célula | C13: =EV.RIESGO!C13 -> Pablo Genaro Sanchez
B14: =EV.RIESGO!B14 -> Líder Técnico | C14: =EV.RIESGO!C14 -> Pablo Genaro Sanchez
A15: =EV.RIESGO!A15 -> Ambiente: | B15: =EV.RIESGO!B15 -> PROD | F15: =EV.RIESGO!F15 -> Componentes a desplegar: | G15: ='INFRA Y DEVOPS'!G15 -> 14
A17: AREAS INVOLUCRADAS
B19: Área | E19: Área Nom | F19: Ejecutor | H19: Back de ejecutor
B20: Selecciona | E20: Selecciona
B21: Administracion de Bases de Datos | E21: DBA | F21: Selecciona
B22: Aplicaciones | E22: APP | F22: =EV.RIESGO!C14 -> Pablo Genaro Sanchez
B23: Ciberseguridad | E23: Ciber | F23: Selecciona
B24: Desarrollo | E24: DEV | F24: =EV.RIESGO!C13 -> Pablo Genaro Sanchez
B25: Devops | E25: Devops | F25: Martin de la Cruz Bartolo
B26: Gestor de identidad y accesos | E26: IAM | F26: Selecciona
B27: Infraestructura Cloud | E27: Cloud | F27: Selecciona
B28: Infraestructura SAP | E28: SAP
B29: Innovación | E29: INOV
B30: Office 365 | E30: Office 365
A33: ACTIVIDADES PREVIAS
A35: No. Tarea | B35: Descripción de la tarea | G35: Servidor | I35: Nubes/Cuenta | J35: Área Nom | K35: Estimación (Minutos) | L35: Hito | M35: Comentarios | P35: Estado
A36: 1 | B36: Ejecutar la migración de tablas de la Base de datos: MacropayVentasApartado; se especifican algunas tablas con la migración con datos: - CM_Ahorro - CM_AhorroMovimiento - CM_Configuracion (Migrar datos) - CM_LogReproceso | G36: bdmpf.macropay.mx | I36: AWS 910617026399 | J36: DBA | P36: En espera
A37: 2 | B37: Crear el Secret Manager con los datos de archivo de variables de entorno para componente: https://github.com/MacropayTD/midd-macropay-club Archivo: env_midd_club_macropay.txt | G37: PROD | I37: AWS 910617026399 | J37: Devops | P37: En espera
A38: 3 | B38: Crear el Pipeline del componente: midd-macropay-club Puerto: 8080 DNS: https://club-macropay.macropay.mx Ingress: / Role: NA | G38: PROD | I38: AWS 910617026399 | J38: Devops | P38: En espera
A39: 4 | B39: Crear usuario srv-macropay-club de base de datos para el componente midd-macropay-club Migrar los permisos de QA3 a PROD | G39: bdmpf.macropay.mx | I39: AWS 910617026399 | J39: DBA | P39: En espera
A40: 5 | B40: Ejecutar los siguientes Scripts en la base de datos MacropayVentasApartado: - 12_INSERT_TYPE_MOVIMENT_BON_v1 | G40: bdmpf.macropay.mx | I40: AWS 910617026399 | J40: DBA
A41: 6 | B41: Ejecutar los siguientes Scripts en la base de datos MacropayPF: - 10_ALTER_TBL_PFM_SolicitudMacropay_v1 - 11_ALTER_TBL_PFM_Carrito_v1 | G41: bdmpf.macropay.mx | I41: AWS 910617026399 | J41: DBA | P41: En espera
A42: 7 | B42: Ejecutar los siguientes Scripts en la base de datos SoftCredito: - 04_alter_add_fgClubMacropay.sql - 06_sp_pfm_solicitud_macropay.sql - 07_sp_gm_SAP_POS_ZVF_Ventas_Financiadas_Encabezado.sql - 08_vw_mpf_SAP_ZVF_ventas_financiadas_encabezado_phx.sql | G42: bdmpf.macropay.mx | I42: AWS 910617026399 | J42: DBA | P42: En espera
A43: 8 | B43: Ejecutar los siguientes Scripts en la base de datos MacropayMobile: - 09_inserts_catCatalogoBeneficios.sql - 05_inserts_catVersionesBeneficios.sql | G43: bdmpf.macropay.mx | I43: AWS 910617026399 | J43: DBA | P43: En espera
A44: 9 | B44: Desplegar componente de mcp-benefits-wallets-api (Pestaña INFRA y DEVOPS) componente #5 | G44: Mulesoft PROD | I44: Mulesoft | J44: DEV | M44: Apoyo MIDD - Equipo Mulesoft | P44: En espera
A45: 10 | B45: Creacion de usuario srv-benefits-wallets-api motor de postgresql (cliente unico) | G45: bdmpf.macropay.mx | I45: AWS 910617026399 | J45: DBA | P45: En espera
A46: 11 | B46: Creacion de usuario srv-benefits-wallets-api motor de sql server | G46: bdmpf.macropay.mx | I46: AWS 910617026399 | J46: DBA | P46: En espera
A47: 12 | B47: Colocacion de las contraseña del usuario srv-benefits-wallets-api del motor de sql server, en el componente mcp-benefits-wallets-api (Mulesoft) en la variable de entorno secure::db.macropayVentasApartado.password | G47: bdmpf.macropay.mx | I47: AWS 910617026399 | J47: IAM | M47: Apoyo MIDD - Equipo Mulesoft | P47: En espera
A48: 13 | B48: Colocacion de las contraseña del usuario srv-benefits-wallets-api del motor de postgresql, en el componente mcp-benefits-wallets-api (Mulesoft) en la variable de entorno secure::db.uniqueCustomer.password | G48: bdmpf.macropay.mx | I48: AWS 910617026399 | J48: IAM | M48: Apoyo MIDD - Equipo Mulesoft | P48: En espera
A49: 14 | B49: Colocacion de las credenciales de Salesforce en el componente mcp-benefits-wallets-api (Mulesoft) en la variables de entorno secure::salesforce.client_id secure::salesforce.client_secret secure::salesforce.token_url | G49: UAT | I49: Salesforce | J49: IAM | M49: Apoyo MIDD - Equipo Mulesoft | P49: En espera
A50: 15 | B50: Agregar las variables en el secret componente: "/EKS/***/productos-financieros/front-pf-calculator" - Archivo: env_front_pf_calculator.txt | G50: AWS PROD | I50: AWS 910617026399 | J50: Devops | P50: En espera
A51: 16 | B51: Cambiar el contenido de la variable “reminderConfig” en Firebase Remote config para el proyecto Macropay-AppV3 y Macropay-IOS, con el contenido del archivo reminderConfig.json | G51: AWS PROD | I51: AWS 910617026399 | J51: Cloud | P51: En espera
P52: Estado
...

Sheet HITOS
A8: =EV.RIESGO!A8 -> ID del proyecto: | B8: =EV.RIESGO!B8 -> com001-pe26 | td029-bf26 | F8: =EV.RIESGO!F8 -> Tipo de Cambio: | G8: =EV.RIESGO!G8 -> Normal | I8: =EV.RIESGO!I8 -> Comentarios adicionales.
A9: =EV.RIESGO!A9 -> Nombre del proyecto | B9: =EV.RIESGO!B9 -> Club Macropay | Compras con Macropesos no descuentan los Macropesos usados a los clientes | F9: =EV.RIESGO!F9 -> Prioridad: | G9: =EV.RIESGO!G9 -> Alta
A10: =EV.RIESGO!A10 -> Plataformas impactadas: | B10: =EV.RIESGO!B10 -> PF, POS, APP, Mulesfort, Salesforce, Infobip | F10: =EV.RIESGO!F10 -> Riesgo: | G10: =EV.RIESGO!G10 -> Medio
A11: =EV.RIESGO!A11 -> Líder del Cambio: | B11: =EV.RIESGO!B11 -> Arquitecto | C11: =EV.RIESGO!C11 -> Henry Suárez Hernández/Jonathan Mauricio López | F11: =EV.RIESGO!F11 -> Afecta la operación: | G11: =EV.RIESGO!G11 -> Si
B12: =EV.RIESGO!B12 -> Project Manager | C12: =EV.RIESGO!C12 -> Maria Alicia Moguel | Ivan Torres
B13: =EV.RIESGO!B13 -> Líder de Célula | C13: =EV.RIESGO!C13 -> Pablo Genaro Sanchez
B14: =EV.RIESGO!B14 -> Líder Técnico | C14: =EV.RIESGO!C14 -> Pablo Genaro Sanchez
A15: =EV.RIESGO!A15 -> Ambiente: | B15: =EV.RIESGO!B15 -> PROD
A18: No. | B18: Descripción de la validación | I18: Área Nom | J18: Identificador | K18: Comentarios
A19: 1 | I19: Selecciona
A20: 2 | I20: Selecciona
A21: 3 | I21: Selecciona
A22: 4 | I22: Selecciona
A23: 5 | I23: Selecciona
A24: 6 | I24: Selecciona
A25: 7 | I25: Selecciona
A26: 8 | I26: Selecciona
A27: 9 | I27: Selecciona
A28: 10 | I28: Selecciona

Sheet INFRA Y DEVOPS
A8: =EV.RIESGO!A8 -> ID del proyecto: | B8: =EV.RIESGO!B8 -> com001-pe26 | td029-bf26 | F8: =EV.RIESGO!F8 -> Tipo de Cambio: | G8: =EV.RIESGO!G8 -> Normal | I8: =EV.RIESGO!I8 -> Comentarios adicionales.
A9: =EV.RIESGO!A9 -> Nombre del proyecto | B9: =EV.RIESGO!B9 -> Club Macropay | Compras con Macropesos no descuentan los Macropesos usados a los clientes | F9: =EV.RIESGO!F9 -> Prioridad: | G9: =EV.RIESGO!G9 -> Alta
A10: =EV.RIESGO!A10 -> Plataformas impactadas: | B10: =EV.RIESGO!B10 -> PF, POS, APP, Mulesfort, Salesforce, Infobip | F10: =EV.RIESGO!F10 -> Riesgo: | G10: =EV.RIESGO!G10 -> Medio
A11: =EV.RIESGO!A11 -> Líder del Cambio: | B11: =EV.RIESGO!B11 -> Arquitecto | C11: =EV.RIESGO!C11 -> Henry Suárez Hernández/Jonathan Mauricio López | F11: =EV.RIESGO!F11 -> Afecta la operación: | G11: =EV.RIESGO!G11 -> Si
B12: =EV.RIESGO!B12 -> Project Manager | C12: =EV.RIESGO!C12 -> Maria Alicia Moguel | Ivan Torres
B13: =EV.RIESGO!B13 -> Líder de Célula | C13: =EV.RIESGO!C13 -> Pablo Genaro Sanchez
B14: =EV.RIESGO!B14 -> Líder Técnico | C14: =EV.RIESGO!C14 -> Pablo Genaro Sanchez
A15: =EV.RIESGO!A15 -> Ambiente: | B15: =EV.RIESGO!B15 -> PROD | F15: =EV.RIESGO!F15 -> Componentes a desplegar: | G15: =COUNTA(B20:AT20) -> 14
B17: 1 | E17: 2 | H17: 3 | K17: 4 | N17: 5 | Q17: 6 | T17: 7 | W17: 8 | Z17: 9 | AC17: 10 | AF17: 11 | AI17: 12 | AL17: 13 | AO17: 14 | AR17: 15
A18: Tipo de Servicio | B18: EKS | E18: Compilado | Ejecutable | H18: EKS | K18: Docker -AWS | N18: Mulesoft | Q18: Selecciona | T18: Selecciona | W18: Salesforce | Z18: Server AWS(EKS) | AC18: Server AWS (EC2) | AF18: Server AWS (EC2) | AI18: Server AWS(EKS) | AL18: Lambda (serveless) | AO18: Lambda (serveless)
A19: Tipo de publicacion | B19: Privado (No se expone a internet) | E19: Público (Se expone a internet) | H19: Privado (No se expone a internet) | K19: Público (Se expone a internet) | N19: Público (Se expone a internet) | Q19: Público (Se expone a internet) | T19: Público (Se expone a internet) | W19: Público (Se expone a internet) | Z19: Privado (No se expone a internet) | AC19: Público (Se expone a internet) | AF19: Público (Se expone a internet) | AI19: Privado (No se expone a internet) | AL19: Privado (No se expone a internet) | AO19: Privado (No se expone a internet)
A20: Repositorio | B20: https://github.com/MacropayTD/POS-service-back | E20: https://github.com/MacropayTD/POS-service-front | H20: https://github.com/MacropayTD/back-api-ec-lealtad | K20: https://github.com/MacropayTD/api-infobip-chatbot | N20: https://github.com/MacropayTD/mcp-benefits-wallets-api | Q20: https://github.com/MacropayTD/front-pf-calculator | T20: https://github.com/MacropayTD/front-pf-payments | W20: NA | Z20: https://github.com/MacropayTD/midd-macropay-club | AC20: https://github.com/MacropayTD/back-apiapp-apartadito | AF20: https://github.com/MacropayTD/back-macropay-api-migracion | AI20: https://github.com/MacropayTD/midd-pf-calculator | AL20: https://github.com/MacropayTD/back-api-ticket-pos | AO20: https://github.com/MacropayTD/midd-pf-sales-summary
A21: Pull Request | B21: #978 | E21: #888 | H21: #147 | K21: #144 | N21: #2 | Q21: #1042 | T21: #616 | W21: NA | Z21: #43 | AC21: #27 | AF21: #110 | AI21: #738 | AL21: #70 | AO21: #550
A22: Ramas de integración | B22: Develop | E22: Develop | H22: Develop | K22: Develop | N22: Develop | Q22: Develop | T22: Develop | W22: NA | Z22: Develop | AC22: Develop | AF22: Develop | AI22: Develop | AL22: Develop | AO22: Develop
A23: Commit | B23: a3769d559875efa8b81dc0a6918ca799ebce3150 | E23: 8666a5ac62bed7130cbdfbdc2d6192c6b8ee57df | H23: d1ead818025d819d99feec759cc92bca979e36c3 | K23: 6a5ca35a9af1f24bd2ce980b708efccd9f628630 | N23: cadd9fecf8c8358eb16c5fabebc1191190d1f50b | Q23: 2bd2c1d75591387fde3f359cdd0437f4961a3ff1 | T23: 49b66556d9e092275f04065cce4765fcdb230acc | W23: WI-000000 | Z23: 655a76f3a6a342d6e8374fedd7484b3a0f9b196a | AC23: 5ce199b12f670033373b3a259b2f87b54c2e1d97 | AF23: 015970ddf7db86e0409be92c306aa13d155b39e7 | AI23: cdcb9450462d8084919ab6792600310d421727f8 | AL23: cd066c9cfd9e0d926792495736aaad289b9a9c83 | AO23: 15d0e403e084cd19979660689d865ca3ae07bfba
A24: Variables de entorno/Web.config /Archivo de despliegue | B24: env_pos_service_back.txt | E24: Mantener mismas variables de entorno. | H24: Mantener mismas variables de entorno. | K24: env_api_infobit_chatbot.txt | N24: Mantener mismas variables de entorno. | Q24: Actualizar la variables de entorno definida en archivo env_front_pf_calculator.txt | T24: Sin cambio de variables | W24: NA | Z24: env_midd_club_macropay.txt | AC24: env_apiapp_apartadito.txt | AF24: Sin cambio de variables de entorno | AI24: env_midd_calculator.txt | AL24: Sin cambio de variables de entorno | AO24: Sin cambio de variables de entorno
A25: URL | B25: https://pxprd.macropay.mx | W25: Sandbox UAT | Z25: https://club-macropay-qa3.macropay.mx
A26: TAG/CECO | W26: Componente Salesforce

Sheet VALIDACIÓN
A8: =EV.RIESGO!A8 -> ID del proyecto: | B8: =EV.RIESGO!B8 -> com001-pe26 | td029-bf26 | F8: =EV.RIESGO!F8 -> Tipo de Cambio: | G8: =EV.RIESGO!G8 -> Normal | I8: =EV.RIESGO!I8 -> Comentarios adicionales. | N8: Avance de despliegue
A9: =EV.RIESGO!A9 -> Nombre del proyecto | B9: =EV.RIESGO!B9 -> Club Macropay | Compras con Macropesos no descuentan los Macropesos usados a los clientes | F9: =EV.RIESGO!F9 -> Prioridad: | G9: =EV.RIESGO!G9 -> Alta | N9: =COUNTIF(N18:R27,"Completado")/(COUNTA(N18:R27)) -> 0
A10: =EV.RIESGO!A10 -> Plataformas impactadas: | B10: =EV.RIESGO!B10 -> PF, POS, APP, Mulesfort, Salesforce, Infobip | F10: =EV.RIESGO!F10 -> Riesgo: | G10: =EV.RIESGO!G10 -> Medio
A11: =EV.RIESGO!A11 -> Líder del Cambio: | B11: =EV.RIESGO!B11 -> Arquitecto | C11: =EV.RIESGO!C11 -> Henry Suárez Hernández/Jonathan Mauricio López | F11: =EV.RIESGO!F11 -> Afecta la operación: | G11: =EV.RIESGO!G11 -> Si
B12: =EV.RIESGO!B12 -> Project Manager | C12: =EV.RIESGO!C12 -> Maria Alicia Moguel | Ivan Torres
B13: =EV.RIESGO!B13 -> Líder de Célula | C13: =EV.RIESGO!C13 -> Pablo Genaro Sanchez
B14: =EV.RIESGO!B14 -> Líder Técnico | C14: =EV.RIESGO!C14 -> Pablo Genaro Sanchez
A15: =EV.RIESGO!A15 -> Ambiente: | B15: =EV.RIESGO!B15 -> PROD
A17: No. | B17: ACTIVIDADES DE VALIDACIÓN | I17: Área Nom | J17: Estimación (Minutos) | K17: Comentarios | N17: Estado
A18: 1 | B18: Pruebas de no afectacion en POS, y validacion de guardado de venta | I18: Selecciona | N18: En espera
A19: 2 | B19: Pruebas de no afectacion en PF | I19: Selecciona | N19: En espera
A20: 3 | I20: Selecciona | N20: En espera
A21: 4 | I21: Selecciona | N21: En espera
A22: 5 | I22: Selecciona | N22: En espera
A23: 6 | I23: Selecciona | N23: En espera
A24: 7 | I24: Selecciona | N24: En espera
A25: 8 | I25: Selecciona | N25: En espera
A26: 9 | I26: Selecciona | N26: En espera
A27: 10 | I27: Selecciona | N27: En espera

Sheet ROLLBACK
A8: =EV.RIESGO!A8 -> ID del proyecto: | B8: =EV.RIESGO!B8 -> com001-pe26 | td029-bf26 | F8: =EV.RIESGO!F8 -> Tipo de Cambio: | G8: =EV.RIESGO!G8 -> Normal | J8: =EV.RIESGO!I8 -> Comentarios adicionales. | O8: Avance de despliegue
A9: =EV.RIESGO!A9 -> Nombre del proyecto | B9: =EV.RIESGO!B9 -> Club Macropay | Compras con Macropesos no descuentan los Macropesos usados a los clientes | F9: =EV.RIESGO!F9 -> Prioridad: | G9: =EV.RIESGO!G9 -> Alta | O9: =COUNTIF(O35:S59,"Completado")/(COUNTA(O35:S41,O50:S59)) -> 0
A10: =EV.RIESGO!A10 -> Plataformas impactadas: | B10: =EV.RIESGO!B10 -> PF, POS, APP, Mulesfort, Salesforce, Infobip | F10: =EV.RIESGO!F10 -> Riesgo: | G10: =EV.RIESGO!G10 -> Medio
A11: =EV.RIESGO!A11 -> Líder del Cambio: | B11: =EV.RIESGO!B11 -> Arquitecto | C11: =EV.RIESGO!C11 -> Henry Suárez Hernández/Jonathan Mauricio López | F11: =EV.RIESGO!F11 -> Afecta la operación: | G11: =EV.RIESGO!G11 -> Si
B12: =EV.RIESGO!B12 -> Project Manager | C12: =EV.RIESGO!C12 -> Maria Alicia Moguel | Ivan Torres
B13: =EV.RIESGO!B13 -> Líder de Célula | C13: =EV.RIESGO!C13 -> Pablo Genaro Sanchez
B14: =EV.RIESGO!B14 -> Líder Técnico | C14: =EV.RIESGO!C14 -> Pablo Genaro Sanchez
A15: =EV.RIESGO!A15 -> Ambiente: | B15: =EV.RIESGO!B15 -> PROD
A17: AREAS INVOLUCRADAS
B19: Área | E19: Área Nom | F19: Ejecutor | H19: Back de ejecutor
B20: Administracion de Bases de Datos | E20: DBA | F20: =RFC!F21 -> Selecciona | H20: =RFC!H21 -> 0
B21: Aplicaciones | E21: APP | F21: =RFC!F22 -> Pablo Genaro Sanchez | H21: =RFC!H22 -> 0
B22: Ciberseguridad | E22: Ciber | F22: =RFC!F23 -> Selecciona | H22: =RFC!H23 -> 0
B23: Desarrollo | E23: DEV | F23: =RFC!F24 -> Pablo Genaro Sanchez | H23: =RFC!H24 -> 0
B24: Devops | E24: Devops | F24: =RFC!F25 -> Martin de la Cruz Bartolo | H24: =RFC!H25 -> 0
B25: Gestor de identidad y accesos | E25: IAM | F25: =RFC!F26 -> Selecciona | H25: =RFC!H26 -> 0
B26: Infraestructura Cloud | E26: Cloud | F26: =RFC!F27 -> Selecciona | H26: =RFC!H27 -> 0
B27: Infraestructura SAP | E27: SAP | F27: =RFC!F28 -> 0 | H27: =RFC!H28 -> 0
B28: Innovación | E28: INOV | F28: =RFC!F29 -> 0 | H28: =RFC!H29 -> 0
B29: Office 365 | E29: Office 365 | F29: =RFC!F30 -> 0 | H29: =RFC!H30 -> 0
F30: =RFC!F31 -> 0 | H30: =RFC!H21 -> 0
A32: ACTIVIDADES DE ROLLBACK
A34: No. Tarea | B34: Descripción de la tarea | G34: Servidor | I34: Nubes/Cuenta | J34: Área Nom | K34: Estimación (Minutos) | L34: Comentarios | O34: Estado
A35: 1 | B35: Realizar el rollback en los componentes afectados en el deploy | G35: AWS QA3 | I35: AWS 910617026399 | J35: Devops | O35: En espera
A36: 3 | B36: Redespliegue de front-pf-calculator de la rama Release | G36: AWS QA4 | I36: AWS 910617026399 | J36: Devops | O36: En espera
A37: 4 | B37: Redespliegue de front-pf-payments de la rama Release | G37: AWS QA5 | I37: AWS 910617026399 | J37: Devops | O37: En espera
A38: 5 | B38: Ejecutar scripts: rollback_catBeneficios | G38: bdmpf.macropay.mx | I38: AWS 910617026399 | J38: DBA | O38: En espera
A39: 6 | B39: Ejecutar scripts: rollback_catMovimiento | G39: bdmpf.macropay.mx | I39: AWS 910617026399 | J39: DBA | O39: En espera
A40: 7 | B40: Ejecutar scripts: rollback_script_carrito_y_solicitud | G40: bdmpf.macropay.mx | I40: AWS 910617026399 | J40: DBA | O40: En espera
A41: 8 | B41: Ejecutar scripts: - vw_mpf_SAP_ZVF_ventas_financiadas_encabezado_phx_PROD - sp_gm_SAP_POS_ZVF_Ventas_Financiadas_Encabezado_PROD - sp_pfm_solicitud_macropay_PROD | G41: bdmpf.macropay.mx | I41: AWS 910617026399 | J41: DBA | O41: En espera
A42: 9 | J42: Selecciona | O42: En espera
A43: 10 | J43: Selecciona | O43: En espera
A44: 11 | J44: Selecciona | O44: En espera
A45: 12 | J45: Selecciona | O45: En espera
A47: ACTIVIDADES DE VALIDACIÓN
A49: No. | B49: Descripción de la validación | J49: Área Nom | K49: Estimación (Minutos) | L49: Comentarios | O49: Estado
A50: 1 | J50: Selecciona | O50: En espera
A51: 2 | J51: Selecciona | O51: En espera
A52: 3 | J52: Selecciona | O52: En espera
A53: 4 | J53: Selecciona | O53: En espera
...

Sheet Lista
B4: Administracion de Bases de Datos | C4: Aplicaciones | D4: Ciberseguridad | E4: Desarrollo | F4: Devops | G4: Gestor de identidad y accesos | H4: Infraestructura Cloud | I4: Infraestructura SAP | J4: Innovación | K4: Office 365
B5: Selecciona | C5: Selecciona | D5: Selecciona | E5: Selecciona | F5: Selecciona | G5: Selecciona | H5: Selecciona | I5: Selecciona | J5: Selecciona | K5: Selecciona
B6: Wille Hans Ditte Morales Sanchez | D6: Jose Angel Morelos Osorio | F6: Alberto Roura Cruz | G6: Carlos Alberto Lopez Mata | H6: Antonio de Jesus Cabanas Buenfil
B7: Eduardo Emmanuel Ravell May | D7: Derian Perez Cortes | F7: Ana Lina Trejo Morales | G7: Christian Uziel Sanchez Alvarez | H7: Diego Vielma Aguilar
B8: Jorge Luis Balam Vargas | D8: Daniela Patricia Ojeda Garcia | F8: Andrei Belyi | G8: Jose Basilio Lopez Mendoza | H8: Eduardo Adrian Magaña Lanz
B9: Gamaliel Uriel Tzab Novelo | D9: Margarita Isabel Camarena Euan | F9: Erick Daniel Orihuela Santillan | H9: Jose Luis Reyes Lopez
B10: Rickey Oswaldo Ehuan Vargas | F10: Fidencio Daniel Santander Reyes | H10: Joset Angel Cervantes Santamaria
F11: Greysi Bianey Cab Chi | H11: Juan Jose Creus Ramos
F12: Hector Alvarez Flores | H12: Luis Angel Bravo Vega
F13: Javier Orlando Castillo Chan | H13: Omar Francisco Canul Mutul
F14: Julio Cesar Ortega Cicero
F15: Martin de la Cruz Bartolo
F16: Nicolas Adrian Angulo Cervera
F17: Santiago Garcia Morales
